2024-07-23 19:43:51,122 - INFO - logging in using static token
2024-07-23 19:43:53,054 - INFO - Shard ID None has connected to Gateway (Session ID: 05135df38ae53203c64bc02569f0bba3).
2024-07-23 19:49:28,210 - INFO - logging in using static token
2024-07-23 19:49:30,200 - INFO - Shard ID None has connected to Gateway (Session ID: dfd60a75877f7447563f561c99825599).
2024-07-23 19:51:17,033 - INFO - logging in using static token
2024-07-23 19:51:19,250 - INFO - Shard ID None has connected to Gateway (Session ID: ae3eef349e9988f597414925ac92daf3).
2024-07-23 20:11:12,189 - INFO - logging in using static token
2024-07-23 20:11:14,102 - INFO - Shard ID None has connected to Gateway (Session ID: 6e459be02a6757fb0a9b7628d44d6bc3).
2024-07-23 20:19:04,685 - INFO - logging in using static token
2024-07-23 20:19:06,927 - INFO - Shard ID None has connected to Gateway (Session ID: 8197c207ac379ceecc0f24713964f49b).
2024-07-23 20:39:24,301 - INFO - logging in using static token
2024-07-23 20:39:26,404 - INFO - Shard ID None has connected to Gateway (Session ID: 671f926ca3fd1353e24fbd40890a7dcb).
2024-07-23 20:44:50,494 - INFO - logging in using static token
2024-07-23 20:44:52,485 - INFO - Shard ID None has connected to Gateway (Session ID: 318bcb6c44760b3b18612090ce285e0e).
2024-07-23 20:45:51,042 - ERROR - Ignoring exception in command 'grouppayout'
Traceback (most recent call last):
  File "C:\Python312\Lib\site-packages\discord\app_commands\tree.py", line 1310, in _call
    await command._invoke_with_namespace(interaction, namespace)
  File "C:\Python312\Lib\site-packages\discord\app_commands\commands.py", line 879, in _invoke_with_namespace
    if not await self._check_can_run(interaction):
           ^^^^^^^^^^^^^^^^^^^^^^^^^^^^^^^^^^^^^^
  File "C:\Python312\Lib\site-packages\discord\app_commands\commands.py", line 1017, in _check_can_run
    return await async_all(f(interaction) for f in predicates)
           ^^^^^^^^^^^^^^^^^^^^^^^^^^^^^^^^^^^^^^^^^^^^^^^^^^^
  File "C:\Python312\Lib\site-packages\discord\utils.py", line 706, in async_all
    elem = await elem
           ^^^^^^^^^^
  File "C:\Users\SOUNAK BERA\Bot Stuff\FundTransfer-Bot\cogs\grouppayout.py", line 19, in predicate
    raise discord.app_commands.MissingPermissions(missing_permissions=role_names)
discord.app_commands.errors.MissingPermissions: You are missing Techie and Admin permission(s) to run this command.
2024-07-23 20:51:21,205 - INFO - logging in using static token
2024-07-23 20:51:23,260 - INFO - Shard ID None has connected to Gateway (Session ID: 9c79b6ffe43af4ca50822040bcbaba57).
2024-07-23 20:52:05,412 - ERROR - Ignoring exception in command 'grouppayout'
Traceback (most recent call last):
  File "C:\Python312\Lib\site-packages\discord\app_commands\tree.py", line 1310, in _call
    await command._invoke_with_namespace(interaction, namespace)
  File "C:\Python312\Lib\site-packages\discord\app_commands\commands.py", line 879, in _invoke_with_namespace
    if not await self._check_can_run(interaction):
           ^^^^^^^^^^^^^^^^^^^^^^^^^^^^^^^^^^^^^^
  File "C:\Python312\Lib\site-packages\discord\app_commands\commands.py", line 1017, in _check_can_run
    return await async_all(f(interaction) for f in predicates)
           ^^^^^^^^^^^^^^^^^^^^^^^^^^^^^^^^^^^^^^^^^^^^^^^^^^^
  File "C:\Python312\Lib\site-packages\discord\utils.py", line 706, in async_all
    elem = await elem
           ^^^^^^^^^^
  File "C:\Users\SOUNAK BERA\Bot Stuff\FundTransfer-Bot\cogs\grouppayout.py", line 19, in predicate
    raise discord.app_commands.MissingPermissions(missing_permissions=role_names)
discord.app_commands.errors.MissingPermissions: You are missing Quartermaster Command and Anotherrolename permission(s) to run this command.
2024-07-23 21:25:52,710 - INFO - logging in using static token
2024-07-23 21:25:54,777 - INFO - Shard ID None has connected to Gateway (Session ID: dc1e4de9718235c6825183eb4613a3df).
2024-07-23 21:26:31,397 - INFO - logging in using static token
2024-07-23 21:26:33,367 - INFO - Shard ID None has connected to Gateway (Session ID: e5c5e03952dbb33a3930e315e07967e3).
2024-07-23 21:27:09,616 - ERROR - Ignoring exception in command 'grouppayout'
Traceback (most recent call last):
  File "C:\Python312\Lib\site-packages\discord\app_commands\tree.py", line 1310, in _call
    await command._invoke_with_namespace(interaction, namespace)
  File "C:\Python312\Lib\site-packages\discord\app_commands\commands.py", line 879, in _invoke_with_namespace
    if not await self._check_can_run(interaction):
           ^^^^^^^^^^^^^^^^^^^^^^^^^^^^^^^^^^^^^^
  File "C:\Python312\Lib\site-packages\discord\app_commands\commands.py", line 1017, in _check_can_run
    return await async_all(f(interaction) for f in predicates)
           ^^^^^^^^^^^^^^^^^^^^^^^^^^^^^^^^^^^^^^^^^^^^^^^^^^^
  File "C:\Python312\Lib\site-packages\discord\utils.py", line 706, in async_all
    elem = await elem
           ^^^^^^^^^^
  File "C:\Users\SOUNAK BERA\Bot Stuff\FundTransfer-Bot\cogs\grouppayout.py", line 19, in predicate
    raise discord.app_commands.MissingPermissions(missing_permissions=role_names)
discord.app_commands.errors.MissingPermissions: You are missing Techie and Admin permission(s) to run this command.
2024-07-23 21:31:05,131 - INFO - logging in using static token
2024-07-23 21:31:07,120 - INFO - Shard ID None has connected to Gateway (Session ID: 3f85e449dc6d3ee097b4683e9829bb5e).
2024-07-23 21:49:58,760 - INFO - logging in using static token
2024-07-23 21:50:00,831 - INFO - Shard ID None has connected to Gateway (Session ID: a26757835fe558e31975cce11ea032f8).
2024-07-23 21:51:14,953 - ERROR - Task exception was never retrieved
future: <Task finished name='CommandTree-invoker' coro=<CommandTree._from_interaction.<locals>.wrapper() done, defined at C:\Python312\Lib\site-packages\discord\app_commands\tree.py:1149> exception=NotFound('404 Not Found (error code: 10015): Unknown Webhook')>
Traceback (most recent call last):
  File "C:\Python312\Lib\site-packages\discord\app_commands\tree.py", line 1310, in _call
    await command._invoke_with_namespace(interaction, namespace)
  File "C:\Python312\Lib\site-packages\discord\app_commands\commands.py", line 879, in _invoke_with_namespace
    if not await self._check_can_run(interaction):
           ^^^^^^^^^^^^^^^^^^^^^^^^^^^^^^^^^^^^^^
  File "C:\Python312\Lib\site-packages\discord\app_commands\commands.py", line 1017, in _check_can_run
    return await async_all(f(interaction) for f in predicates)
           ^^^^^^^^^^^^^^^^^^^^^^^^^^^^^^^^^^^^^^^^^^^^^^^^^^^
  File "C:\Python312\Lib\site-packages\discord\utils.py", line 706, in async_all
    elem = await elem
           ^^^^^^^^^^
  File "C:\Users\SOUNAK BERA\Bot Stuff\FundTransfer-Bot\cogs\grouppayout.py", line 19, in predicate
    raise discord.app_commands.MissingPermissions(missing_permissions=role_names)
discord.app_commands.errors.MissingPermissions: You are missing Techie and Admin permission(s) to run this command.

During handling of the above exception, another exception occurred:

Traceback (most recent call last):
  File "C:\Python312\Lib\site-packages\discord\app_commands\tree.py", line 1151, in wrapper
    await self._call(interaction)
  File "C:\Python312\Lib\site-packages\discord\app_commands\tree.py", line 1313, in _call
    await command._invoke_error_handlers(interaction, e)
  File "C:\Python312\Lib\site-packages\discord\app_commands\commands.py", line 800, in _invoke_error_handlers
    await self.on_error(self.binding, interaction, error)  # type: ignore
    ^^^^^^^^^^^^^^^^^^^^^^^^^^^^^^^^^^^^^^^^^^^^^^^^^^^^^
  File "C:\Users\SOUNAK BERA\Bot Stuff\FundTransfer-Bot\cogs\grouppayout.py", line 132, in group_payout_error
    await interaction.followup.send(f"You do not have the required roles to use this command: {missing_roles}", ephemeral=True)
  File "C:\Python312\Lib\site-packages\discord\webhook\async_.py", line 1843, in send
    data = await adapter.execute_webhook(
           ^^^^^^^^^^^^^^^^^^^^^^^^^^^^^^
  File "C:\Python312\Lib\site-packages\discord\webhook\async_.py", line 221, in request
    raise NotFound(response, data)
discord.errors.NotFound: 404 Not Found (error code: 10015): Unknown Webhook
2024-07-23 21:51:40,292 - INFO - logging in using static token
2024-07-23 21:51:42,165 - INFO - Shard ID None has connected to Gateway (Session ID: 72b72ae6956ab7240be4becd2e040851).
2024-07-23 21:52:26,810 - ERROR - Task exception was never retrieved
future: <Task finished name='CommandTree-invoker' coro=<CommandTree._from_interaction.<locals>.wrapper() done, defined at C:\Python312\Lib\site-packages\discord\app_commands\tree.py:1149> exception=NotFound('404 Not Found (error code: 10015): Unknown Webhook')>
Traceback (most recent call last):
  File "C:\Users\SOUNAK BERA\Bot Stuff\FundTransfer-Bot\cogs\grouppayout.py", line 120, in group_payout
    await interaction.followup.send(embed=embed)
  File "C:\Python312\Lib\site-packages\discord\webhook\async_.py", line 1843, in send
    data = await adapter.execute_webhook(
           ^^^^^^^^^^^^^^^^^^^^^^^^^^^^^^
  File "C:\Python312\Lib\site-packages\discord\webhook\async_.py", line 221, in request
    raise NotFound(response, data)
discord.errors.NotFound: 404 Not Found (error code: 10015): Unknown Webhook

During handling of the above exception, another exception occurred:

Traceback (most recent call last):
  File "C:\Python312\Lib\site-packages\discord\app_commands\commands.py", line 857, in _do_call
    return await self._callback(self.binding, interaction, **params)  # type: ignore
           ^^^^^^^^^^^^^^^^^^^^^^^^^^^^^^^^^^^^^^^^^^^^^^^^^^^^^^^^^
  File "C:\Users\SOUNAK BERA\Bot Stuff\FundTransfer-Bot\cogs\grouppayout.py", line 126, in group_payout
    await interaction.followup.send(embed=embed)
  File "C:\Python312\Lib\site-packages\discord\webhook\async_.py", line 1843, in send
    data = await adapter.execute_webhook(
           ^^^^^^^^^^^^^^^^^^^^^^^^^^^^^^
  File "C:\Python312\Lib\site-packages\discord\webhook\async_.py", line 221, in request
    raise NotFound(response, data)
discord.errors.NotFound: 404 Not Found (error code: 10015): Unknown Webhook

The above exception was the direct cause of the following exception:

Traceback (most recent call last):
  File "C:\Python312\Lib\site-packages\discord\app_commands\tree.py", line 1310, in _call
    await command._invoke_with_namespace(interaction, namespace)
  File "C:\Python312\Lib\site-packages\discord\app_commands\commands.py", line 883, in _invoke_with_namespace
    return await self._do_call(interaction, transformed_values)
           ^^^^^^^^^^^^^^^^^^^^^^^^^^^^^^^^^^^^^^^^^^^^^^^^^^^^
  File "C:\Python312\Lib\site-packages\discord\app_commands\commands.py", line 876, in _do_call
    raise CommandInvokeError(self, e) from e
discord.app_commands.errors.CommandInvokeError: Command 'grouppayout' raised an exception: NotFound: 404 Not Found (error code: 10015): Unknown Webhook

During handling of the above exception, another exception occurred:

Traceback (most recent call last):
  File "C:\Python312\Lib\site-packages\discord\app_commands\tree.py", line 1151, in wrapper
    await self._call(interaction)
  File "C:\Python312\Lib\site-packages\discord\app_commands\tree.py", line 1313, in _call
    await command._invoke_error_handlers(interaction, e)
  File "C:\Python312\Lib\site-packages\discord\app_commands\commands.py", line 800, in _invoke_error_handlers
    await self.on_error(self.binding, interaction, error)  # type: ignore
    ^^^^^^^^^^^^^^^^^^^^^^^^^^^^^^^^^^^^^^^^^^^^^^^^^^^^^
  File "C:\Users\SOUNAK BERA\Bot Stuff\FundTransfer-Bot\cogs\grouppayout.py", line 134, in group_payout_error
    await interaction.followup.send(f"An error occurred: {str(error)}", ephemeral=True)
  File "C:\Python312\Lib\site-packages\discord\webhook\async_.py", line 1843, in send
    data = await adapter.execute_webhook(
           ^^^^^^^^^^^^^^^^^^^^^^^^^^^^^^
  File "C:\Python312\Lib\site-packages\discord\webhook\async_.py", line 221, in request
    raise NotFound(response, data)
discord.errors.NotFound: 404 Not Found (error code: 10015): Unknown Webhook
2024-07-23 22:09:53,336 - INFO - logging in using static token
2024-07-23 22:09:55,274 - INFO - Shard ID None has connected to Gateway (Session ID: 957774236ea1ec9e1f12ddb242fa120f).
2024-07-23 22:13:25,554 - ERROR - Task exception was never retrieved
future: <Task finished name='CommandTree-invoker' coro=<CommandTree._from_interaction.<locals>.wrapper() done, defined at C:\Python312\Lib\site-packages\discord\app_commands\tree.py:1149> exception=NotFound('404 Not Found (error code: 10015): Unknown Webhook')>
Traceback (most recent call last):
  File "C:\Python312\Lib\site-packages\discord\app_commands\tree.py", line 1310, in _call
    await command._invoke_with_namespace(interaction, namespace)
  File "C:\Python312\Lib\site-packages\discord\app_commands\commands.py", line 879, in _invoke_with_namespace
    if not await self._check_can_run(interaction):
           ^^^^^^^^^^^^^^^^^^^^^^^^^^^^^^^^^^^^^^
  File "C:\Python312\Lib\site-packages\discord\app_commands\commands.py", line 1017, in _check_can_run
    return await async_all(f(interaction) for f in predicates)
           ^^^^^^^^^^^^^^^^^^^^^^^^^^^^^^^^^^^^^^^^^^^^^^^^^^^
  File "C:\Python312\Lib\site-packages\discord\utils.py", line 706, in async_all
    elem = await elem
           ^^^^^^^^^^
  File "C:\Users\SOUNAK BERA\Bot Stuff\FundTransfer-Bot\cogs\grouppayout.py", line 17, in predicate
    raise discord.app_commands.MissingPermissions(missing_permissions=role_names)
discord.app_commands.errors.MissingPermissions: You are missing Quartermaster Command and Anotherrolename permission(s) to run this command.

During handling of the above exception, another exception occurred:

Traceback (most recent call last):
  File "C:\Python312\Lib\site-packages\discord\app_commands\tree.py", line 1151, in wrapper
    await self._call(interaction)
  File "C:\Python312\Lib\site-packages\discord\app_commands\tree.py", line 1313, in _call
    await command._invoke_error_handlers(interaction, e)
  File "C:\Python312\Lib\site-packages\discord\app_commands\commands.py", line 800, in _invoke_error_handlers
    await self.on_error(self.binding, interaction, error)  # type: ignore
    ^^^^^^^^^^^^^^^^^^^^^^^^^^^^^^^^^^^^^^^^^^^^^^^^^^^^^
  File "C:\Users\SOUNAK BERA\Bot Stuff\FundTransfer-Bot\cogs\grouppayout.py", line 131, in group_payout_error
    await interaction.followup.send(f"You do not have the required roles to use this command: {missing_roles}", ephemeral=True)
  File "C:\Python312\Lib\site-packages\discord\webhook\async_.py", line 1843, in send
    data = await adapter.execute_webhook(
           ^^^^^^^^^^^^^^^^^^^^^^^^^^^^^^
  File "C:\Python312\Lib\site-packages\discord\webhook\async_.py", line 221, in request
    raise NotFound(response, data)
discord.errors.NotFound: 404 Not Found (error code: 10015): Unknown Webhook
2024-07-23 22:18:40,840 - INFO - logging in using static token
2024-07-23 22:18:42,934 - INFO - Shard ID None has connected to Gateway (Session ID: 210031230080471aea97beed81f8006f).
2024-07-23 22:19:28,399 - ERROR - Task exception was never retrieved
future: <Task finished name='CommandTree-invoker' coro=<CommandTree._from_interaction.<locals>.wrapper() done, defined at C:\Python312\Lib\site-packages\discord\app_commands\tree.py:1149> exception=NotFound('404 Not Found (error code: 10015): Unknown Webhook')>
Traceback (most recent call last):
  File "C:\Python312\Lib\site-packages\discord\app_commands\tree.py", line 1310, in _call
    await command._invoke_with_namespace(interaction, namespace)
  File "C:\Python312\Lib\site-packages\discord\app_commands\commands.py", line 879, in _invoke_with_namespace
    if not await self._check_can_run(interaction):
           ^^^^^^^^^^^^^^^^^^^^^^^^^^^^^^^^^^^^^^
  File "C:\Python312\Lib\site-packages\discord\app_commands\commands.py", line 1017, in _check_can_run
    return await async_all(f(interaction) for f in predicates)
           ^^^^^^^^^^^^^^^^^^^^^^^^^^^^^^^^^^^^^^^^^^^^^^^^^^^
  File "C:\Python312\Lib\site-packages\discord\utils.py", line 706, in async_all
    elem = await elem
           ^^^^^^^^^^
  File "C:\Users\SOUNAK BERA\Bot Stuff\FundTransfer-Bot\cogs\grouppayout.py", line 17, in predicate
    raise discord.app_commands.MissingPermissions(missing_permissions=role_names)
discord.app_commands.errors.MissingPermissions: You are missing Techie and Admin permission(s) to run this command.

During handling of the above exception, another exception occurred:

Traceback (most recent call last):
  File "C:\Python312\Lib\site-packages\discord\app_commands\tree.py", line 1151, in wrapper
    await self._call(interaction)
  File "C:\Python312\Lib\site-packages\discord\app_commands\tree.py", line 1313, in _call
    await command._invoke_error_handlers(interaction, e)
  File "C:\Python312\Lib\site-packages\discord\app_commands\commands.py", line 800, in _invoke_error_handlers
    await self.on_error(self.binding, interaction, error)  # type: ignore
    ^^^^^^^^^^^^^^^^^^^^^^^^^^^^^^^^^^^^^^^^^^^^^^^^^^^^^
  File "C:\Users\SOUNAK BERA\Bot Stuff\FundTransfer-Bot\cogs\grouppayout.py", line 131, in group_payout_error
    await interaction.followup.send(f"You do not have the required roles to use this command: {missing_roles}", ephemeral=True)
  File "C:\Python312\Lib\site-packages\discord\webhook\async_.py", line 1843, in send
    data = await adapter.execute_webhook(
           ^^^^^^^^^^^^^^^^^^^^^^^^^^^^^^
  File "C:\Python312\Lib\site-packages\discord\webhook\async_.py", line 221, in request
    raise NotFound(response, data)
discord.errors.NotFound: 404 Not Found (error code: 10015): Unknown Webhook
2024-07-23 22:19:59,284 - ERROR - Task exception was never retrieved
future: <Task finished name='CommandTree-invoker' coro=<CommandTree._from_interaction.<locals>.wrapper() done, defined at C:\Python312\Lib\site-packages\discord\app_commands\tree.py:1149> exception=NotFound('404 Not Found (error code: 10015): Unknown Webhook')>
Traceback (most recent call last):
  File "C:\Python312\Lib\site-packages\discord\app_commands\tree.py", line 1310, in _call
    await command._invoke_with_namespace(interaction, namespace)
  File "C:\Python312\Lib\site-packages\discord\app_commands\commands.py", line 879, in _invoke_with_namespace
    if not await self._check_can_run(interaction):
           ^^^^^^^^^^^^^^^^^^^^^^^^^^^^^^^^^^^^^^
  File "C:\Python312\Lib\site-packages\discord\app_commands\commands.py", line 1017, in _check_can_run
    return await async_all(f(interaction) for f in predicates)
           ^^^^^^^^^^^^^^^^^^^^^^^^^^^^^^^^^^^^^^^^^^^^^^^^^^^
  File "C:\Python312\Lib\site-packages\discord\utils.py", line 706, in async_all
    elem = await elem
           ^^^^^^^^^^
  File "C:\Users\SOUNAK BERA\Bot Stuff\FundTransfer-Bot\cogs\grouppayout.py", line 17, in predicate
    raise discord.app_commands.MissingPermissions(missing_permissions=role_names)
discord.app_commands.errors.MissingPermissions: You are missing Techie and Admin permission(s) to run this command.

During handling of the above exception, another exception occurred:

Traceback (most recent call last):
  File "C:\Python312\Lib\site-packages\discord\app_commands\tree.py", line 1151, in wrapper
    await self._call(interaction)
  File "C:\Python312\Lib\site-packages\discord\app_commands\tree.py", line 1313, in _call
    await command._invoke_error_handlers(interaction, e)
  File "C:\Python312\Lib\site-packages\discord\app_commands\commands.py", line 800, in _invoke_error_handlers
    await self.on_error(self.binding, interaction, error)  # type: ignore
    ^^^^^^^^^^^^^^^^^^^^^^^^^^^^^^^^^^^^^^^^^^^^^^^^^^^^^
  File "C:\Users\SOUNAK BERA\Bot Stuff\FundTransfer-Bot\cogs\grouppayout.py", line 131, in group_payout_error
    await interaction.followup.send(f"You do not have the required roles to use this command: {missing_roles}", ephemeral=True)
  File "C:\Python312\Lib\site-packages\discord\webhook\async_.py", line 1843, in send
    data = await adapter.execute_webhook(
           ^^^^^^^^^^^^^^^^^^^^^^^^^^^^^^
  File "C:\Python312\Lib\site-packages\discord\webhook\async_.py", line 221, in request
    raise NotFound(response, data)
discord.errors.NotFound: 404 Not Found (error code: 10015): Unknown Webhook
2024-07-23 22:27:43,277 - INFO - logging in using static token
2024-07-23 22:27:45,250 - INFO - Shard ID None has connected to Gateway (Session ID: e2076f43eb2c8cecc06e5894ba6a881a).
2024-07-23 22:28:34,468 - ERROR - Task exception was never retrieved
future: <Task finished name='CommandTree-invoker' coro=<CommandTree._from_interaction.<locals>.wrapper() done, defined at C:\Python312\Lib\site-packages\discord\app_commands\tree.py:1149> exception=NotFound('404 Not Found (error code: 10062): Unknown interaction')>
Traceback (most recent call last):
  File "C:\Users\SOUNAK BERA\Bot Stuff\FundTransfer-Bot\cogs\grouppayout.py", line 117, in group_payout
    await interaction.response.send_message(embed=embed)
  File "C:\Python312\Lib\site-packages\discord\interactions.py", line 855, in send_message
    await adapter.create_interaction_response(
  File "C:\Python312\Lib\site-packages\discord\webhook\async_.py", line 221, in request
    raise NotFound(response, data)
discord.errors.NotFound: 404 Not Found (error code: 10062): Unknown interaction

During handling of the above exception, another exception occurred:

Traceback (most recent call last):
  File "C:\Python312\Lib\site-packages\discord\app_commands\commands.py", line 857, in _do_call
    return await self._callback(self.binding, interaction, **params)  # type: ignore
           ^^^^^^^^^^^^^^^^^^^^^^^^^^^^^^^^^^^^^^^^^^^^^^^^^^^^^^^^^
  File "C:\Users\SOUNAK BERA\Bot Stuff\FundTransfer-Bot\cogs\grouppayout.py", line 123, in group_payout
    await interaction.response.send_message(embed=embed)
  File "C:\Python312\Lib\site-packages\discord\interactions.py", line 855, in send_message
    await adapter.create_interaction_response(
  File "C:\Python312\Lib\site-packages\discord\webhook\async_.py", line 221, in request
    raise NotFound(response, data)
discord.errors.NotFound: 404 Not Found (error code: 10062): Unknown interaction

The above exception was the direct cause of the following exception:

Traceback (most recent call last):
  File "C:\Python312\Lib\site-packages\discord\app_commands\tree.py", line 1310, in _call
    await command._invoke_with_namespace(interaction, namespace)
  File "C:\Python312\Lib\site-packages\discord\app_commands\commands.py", line 883, in _invoke_with_namespace
    return await self._do_call(interaction, transformed_values)
           ^^^^^^^^^^^^^^^^^^^^^^^^^^^^^^^^^^^^^^^^^^^^^^^^^^^^
  File "C:\Python312\Lib\site-packages\discord\app_commands\commands.py", line 876, in _do_call
    raise CommandInvokeError(self, e) from e
discord.app_commands.errors.CommandInvokeError: Command 'grouppayout' raised an exception: NotFound: 404 Not Found (error code: 10062): Unknown interaction

During handling of the above exception, another exception occurred:

Traceback (most recent call last):
  File "C:\Python312\Lib\site-packages\discord\app_commands\tree.py", line 1151, in wrapper
    await self._call(interaction)
  File "C:\Python312\Lib\site-packages\discord\app_commands\tree.py", line 1313, in _call
    await command._invoke_error_handlers(interaction, e)
  File "C:\Python312\Lib\site-packages\discord\app_commands\commands.py", line 800, in _invoke_error_handlers
    await self.on_error(self.binding, interaction, error)  # type: ignore
    ^^^^^^^^^^^^^^^^^^^^^^^^^^^^^^^^^^^^^^^^^^^^^^^^^^^^^
  File "C:\Users\SOUNAK BERA\Bot Stuff\FundTransfer-Bot\cogs\grouppayout.py", line 131, in group_payout_error
    await interaction.response.send_message(f"An error occurred: {str(error)}", ephemeral=True)
  File "C:\Python312\Lib\site-packages\discord\interactions.py", line 855, in send_message
    await adapter.create_interaction_response(
  File "C:\Python312\Lib\site-packages\discord\webhook\async_.py", line 221, in request
    raise NotFound(response, data)
discord.errors.NotFound: 404 Not Found (error code: 10062): Unknown interaction
2024-07-23 22:34:29,454 - INFO - logging in using static token
2024-07-23 22:34:31,614 - INFO - Shard ID None has connected to Gateway (Session ID: 169072f2a2a4d07a04438e5347553b56).
2024-07-23 22:35:58,669 - INFO - logging in using static token
2024-07-23 22:36:00,573 - INFO - Shard ID None has connected to Gateway (Session ID: 0110581d615a9ed86b64bdc8b8647fae).
2024-07-23 22:37:01,239 - ERROR - Task exception was never retrieved
future: <Task finished name='CommandTree-invoker' coro=<CommandTree._from_interaction.<locals>.wrapper() done, defined at C:\Python312\Lib\site-packages\discord\app_commands\tree.py:1149> exception=NotFound('404 Not Found (error code: 10062): Unknown interaction')>
Traceback (most recent call last):
  File "C:\Users\SOUNAK BERA\Bot Stuff\FundTransfer-Bot\cogs\grouppayout.py", line 120, in group_payout
    await interaction.response.send_message(embed=embed, ephemeral=True)
  File "C:\Python312\Lib\site-packages\discord\interactions.py", line 855, in send_message
    await adapter.create_interaction_response(
  File "C:\Python312\Lib\site-packages\discord\webhook\async_.py", line 221, in request
    raise NotFound(response, data)
discord.errors.NotFound: 404 Not Found (error code: 10062): Unknown interaction

During handling of the above exception, another exception occurred:

Traceback (most recent call last):
  File "C:\Python312\Lib\site-packages\discord\app_commands\commands.py", line 857, in _do_call
    return await self._callback(self.binding, interaction, **params)  # type: ignore
           ^^^^^^^^^^^^^^^^^^^^^^^^^^^^^^^^^^^^^^^^^^^^^^^^^^^^^^^^^
  File "C:\Users\SOUNAK BERA\Bot Stuff\FundTransfer-Bot\cogs\grouppayout.py", line 126, in group_payout
    await interaction.response.send_message(embed=embed, ephemeral=True)
  File "C:\Python312\Lib\site-packages\discord\interactions.py", line 855, in send_message
    await adapter.create_interaction_response(
  File "C:\Python312\Lib\site-packages\discord\webhook\async_.py", line 221, in request
    raise NotFound(response, data)
discord.errors.NotFound: 404 Not Found (error code: 10062): Unknown interaction

The above exception was the direct cause of the following exception:

Traceback (most recent call last):
  File "C:\Python312\Lib\site-packages\discord\app_commands\tree.py", line 1310, in _call
    await command._invoke_with_namespace(interaction, namespace)
  File "C:\Python312\Lib\site-packages\discord\app_commands\commands.py", line 883, in _invoke_with_namespace
    return await self._do_call(interaction, transformed_values)
           ^^^^^^^^^^^^^^^^^^^^^^^^^^^^^^^^^^^^^^^^^^^^^^^^^^^^
  File "C:\Python312\Lib\site-packages\discord\app_commands\commands.py", line 876, in _do_call
    raise CommandInvokeError(self, e) from e
discord.app_commands.errors.CommandInvokeError: Command 'grouppayout' raised an exception: NotFound: 404 Not Found (error code: 10062): Unknown interaction

During handling of the above exception, another exception occurred:

Traceback (most recent call last):
  File "C:\Python312\Lib\site-packages\discord\app_commands\tree.py", line 1151, in wrapper
    await self._call(interaction)
  File "C:\Python312\Lib\site-packages\discord\app_commands\tree.py", line 1313, in _call
    await command._invoke_error_handlers(interaction, e)
  File "C:\Python312\Lib\site-packages\discord\app_commands\commands.py", line 800, in _invoke_error_handlers
    await self.on_error(self.binding, interaction, error)  # type: ignore
    ^^^^^^^^^^^^^^^^^^^^^^^^^^^^^^^^^^^^^^^^^^^^^^^^^^^^^
  File "C:\Users\SOUNAK BERA\Bot Stuff\FundTransfer-Bot\cogs\grouppayout.py", line 135, in group_payout_error
    await interaction.response.send_message(f"An error occurred: {str(error)}", ephemeral=True)
  File "C:\Python312\Lib\site-packages\discord\interactions.py", line 855, in send_message
    await adapter.create_interaction_response(
  File "C:\Python312\Lib\site-packages\discord\webhook\async_.py", line 221, in request
    raise NotFound(response, data)
discord.errors.NotFound: 404 Not Found (error code: 10062): Unknown interaction
2024-07-23 22:39:17,064 - INFO - logging in using static token
2024-07-23 22:39:19,240 - INFO - Shard ID None has connected to Gateway (Session ID: 4fb9adc107c5772c71b268a57c9f1d33).
2024-07-23 22:39:51,960 - ERROR - Task exception was never retrieved
future: <Task finished name='CommandTree-invoker' coro=<CommandTree._from_interaction.<locals>.wrapper() done, defined at C:\Python312\Lib\site-packages\discord\app_commands\tree.py:1149> exception=NotFound('404 Not Found (error code: 10015): Unknown Webhook')>
Traceback (most recent call last):
  File "C:\Python312\Lib\site-packages\discord\app_commands\tree.py", line 1310, in _call
    await command._invoke_with_namespace(interaction, namespace)
  File "C:\Python312\Lib\site-packages\discord\app_commands\commands.py", line 879, in _invoke_with_namespace
    if not await self._check_can_run(interaction):
           ^^^^^^^^^^^^^^^^^^^^^^^^^^^^^^^^^^^^^^
  File "C:\Python312\Lib\site-packages\discord\app_commands\commands.py", line 1017, in _check_can_run
    return await async_all(f(interaction) for f in predicates)
           ^^^^^^^^^^^^^^^^^^^^^^^^^^^^^^^^^^^^^^^^^^^^^^^^^^^
  File "C:\Python312\Lib\site-packages\discord\utils.py", line 706, in async_all
    elem = await elem
           ^^^^^^^^^^
  File "C:\Users\SOUNAK BERA\Bot Stuff\FundTransfer-Bot\cogs\grouppayout.py", line 17, in predicate
    raise discord.app_commands.MissingPermissions(missing_permissions=role_names)
discord.app_commands.errors.MissingPermissions: You are missing Quartermaster Command and Anotherrolename permission(s) to run this command.

During handling of the above exception, another exception occurred:

Traceback (most recent call last):
  File "C:\Python312\Lib\site-packages\discord\app_commands\tree.py", line 1151, in wrapper
    await self._call(interaction)
  File "C:\Python312\Lib\site-packages\discord\app_commands\tree.py", line 1313, in _call
    await command._invoke_error_handlers(interaction, e)
  File "C:\Python312\Lib\site-packages\discord\app_commands\commands.py", line 800, in _invoke_error_handlers
    await self.on_error(self.binding, interaction, error)  # type: ignore
    ^^^^^^^^^^^^^^^^^^^^^^^^^^^^^^^^^^^^^^^^^^^^^^^^^^^^^
  File "C:\Users\SOUNAK BERA\Bot Stuff\FundTransfer-Bot\cogs\grouppayout.py", line 134, in group_payout_error
    await interaction.followup.send(f"You do not have the required roles to use this command: {missing_roles}", ephemeral=True)
  File "C:\Python312\Lib\site-packages\discord\webhook\async_.py", line 1843, in send
    data = await adapter.execute_webhook(
           ^^^^^^^^^^^^^^^^^^^^^^^^^^^^^^
  File "C:\Python312\Lib\site-packages\discord\webhook\async_.py", line 221, in request
    raise NotFound(response, data)
discord.errors.NotFound: 404 Not Found (error code: 10015): Unknown Webhook
2024-07-23 22:44:07,917 - INFO - logging in using static token
2024-07-23 22:44:09,863 - INFO - Shard ID None has connected to Gateway (Session ID: 39db825581702e99e0d0d9d51453118d).
2024-07-23 22:45:10,654 - INFO - logging in using static token
2024-07-23 22:45:12,547 - INFO - Shard ID None has connected to Gateway (Session ID: 161d29fe534f2ef57abb48b6b8fc2ef1).
2024-07-23 22:53:35,491 - INFO - logging in using static token
2024-07-23 22:53:37,552 - INFO - Shard ID None has connected to Gateway (Session ID: da680a70eddd9aa9524b2f9a42e7f7d1).
2024-07-23 23:00:23,356 - INFO - logging in using static token
2024-07-23 23:00:25,200 - INFO - Shard ID None has connected to Gateway (Session ID: fc3028333952bfb7216e640eaac7c6d4).
2024-07-23 23:01:32,678 - ERROR - Task exception was never retrieved
future: <Task finished name='CommandTree-invoker' coro=<CommandTree._from_interaction.<locals>.wrapper() done, defined at C:\Python312\Lib\site-packages\discord\app_commands\tree.py:1149> exception=NotFound('404 Not Found (error code: 10015): Unknown Webhook')>
Traceback (most recent call last):
  File "C:\Python312\Lib\site-packages\discord\app_commands\tree.py", line 1310, in _call
    await command._invoke_with_namespace(interaction, namespace)
  File "C:\Python312\Lib\site-packages\discord\app_commands\commands.py", line 879, in _invoke_with_namespace
    if not await self._check_can_run(interaction):
           ^^^^^^^^^^^^^^^^^^^^^^^^^^^^^^^^^^^^^^
  File "C:\Python312\Lib\site-packages\discord\app_commands\commands.py", line 1017, in _check_can_run
    return await async_all(f(interaction) for f in predicates)
           ^^^^^^^^^^^^^^^^^^^^^^^^^^^^^^^^^^^^^^^^^^^^^^^^^^^
  File "C:\Python312\Lib\site-packages\discord\utils.py", line 706, in async_all
    elem = await elem
           ^^^^^^^^^^
  File "C:\Users\SOUNAK BERA\Bot Stuff\FundTransfer-Bot\cogs\grouppayout.py", line 17, in predicate
    raise discord.app_commands.MissingPermissions(missing_permissions=role_names)
discord.app_commands.errors.MissingPermissions: You are missing Quartermaster Command and Anotherrolename permission(s) to run this command.

During handling of the above exception, another exception occurred:

Traceback (most recent call last):
  File "C:\Python312\Lib\site-packages\discord\app_commands\tree.py", line 1151, in wrapper
    await self._call(interaction)
  File "C:\Python312\Lib\site-packages\discord\app_commands\tree.py", line 1313, in _call
    await command._invoke_error_handlers(interaction, e)
  File "C:\Python312\Lib\site-packages\discord\app_commands\commands.py", line 800, in _invoke_error_handlers
    await self.on_error(self.binding, interaction, error)  # type: ignore
    ^^^^^^^^^^^^^^^^^^^^^^^^^^^^^^^^^^^^^^^^^^^^^^^^^^^^^
  File "C:\Users\SOUNAK BERA\Bot Stuff\FundTransfer-Bot\cogs\grouppayout.py", line 137, in group_payout_error
    await interaction.followup.send(f"You do not have the required roles to use this command: {missing_roles}", ephemeral=True)
  File "C:\Python312\Lib\site-packages\discord\webhook\async_.py", line 1843, in send
    data = await adapter.execute_webhook(
           ^^^^^^^^^^^^^^^^^^^^^^^^^^^^^^
  File "C:\Python312\Lib\site-packages\discord\webhook\async_.py", line 221, in request
    raise NotFound(response, data)
discord.errors.NotFound: 404 Not Found (error code: 10015): Unknown Webhook
2024-07-23 23:02:50,187 - INFO - logging in using static token
2024-07-23 23:02:52,362 - INFO - Shard ID None has connected to Gateway (Session ID: 18284803886225812ec12699e4dc03be).
2024-07-23 23:03:15,863 - INFO - logging in using static token
2024-07-23 23:03:17,828 - INFO - Shard ID None has connected to Gateway (Session ID: 15ca03267544254c83168933997b24f3).
2024-07-23 23:04:35,867 - ERROR - Task exception was never retrieved
future: <Task finished name='CommandTree-invoker' coro=<CommandTree._from_interaction.<locals>.wrapper() done, defined at C:\Python312\Lib\site-packages\discord\app_commands\tree.py:1149> exception=NotFound('404 Not Found (error code: 10015): Unknown Webhook')>
Traceback (most recent call last):
  File "C:\Python312\Lib\site-packages\discord\app_commands\tree.py", line 1310, in _call
    await command._invoke_with_namespace(interaction, namespace)
  File "C:\Python312\Lib\site-packages\discord\app_commands\commands.py", line 879, in _invoke_with_namespace
    if not await self._check_can_run(interaction):
           ^^^^^^^^^^^^^^^^^^^^^^^^^^^^^^^^^^^^^^
  File "C:\Python312\Lib\site-packages\discord\app_commands\commands.py", line 1017, in _check_can_run
    return await async_all(f(interaction) for f in predicates)
           ^^^^^^^^^^^^^^^^^^^^^^^^^^^^^^^^^^^^^^^^^^^^^^^^^^^
  File "C:\Python312\Lib\site-packages\discord\utils.py", line 706, in async_all
    elem = await elem
           ^^^^^^^^^^
  File "C:\Users\SOUNAK BERA\Bot Stuff\FundTransfer-Bot\cogs\grouppayout.py", line 17, in predicate
    raise discord.app_commands.MissingPermissions(missing_permissions=role_names)
discord.app_commands.errors.MissingPermissions: You are missing Quartermaster Command and Techie permission(s) to run this command.

During handling of the above exception, another exception occurred:

Traceback (most recent call last):
  File "C:\Python312\Lib\site-packages\discord\app_commands\tree.py", line 1151, in wrapper
    await self._call(interaction)
  File "C:\Python312\Lib\site-packages\discord\app_commands\tree.py", line 1313, in _call
    await command._invoke_error_handlers(interaction, e)
  File "C:\Python312\Lib\site-packages\discord\app_commands\commands.py", line 800, in _invoke_error_handlers
    await self.on_error(self.binding, interaction, error)  # type: ignore
    ^^^^^^^^^^^^^^^^^^^^^^^^^^^^^^^^^^^^^^^^^^^^^^^^^^^^^
  File "C:\Users\SOUNAK BERA\Bot Stuff\FundTransfer-Bot\cogs\grouppayout.py", line 136, in group_payout_error
    await interaction.followup.send(f"You do not have the required roles to use this command: {missing_roles}", ephemeral=True)
  File "C:\Python312\Lib\site-packages\discord\webhook\async_.py", line 1843, in send
    data = await adapter.execute_webhook(
           ^^^^^^^^^^^^^^^^^^^^^^^^^^^^^^
  File "C:\Python312\Lib\site-packages\discord\webhook\async_.py", line 221, in request
    raise NotFound(response, data)
discord.errors.NotFound: 404 Not Found (error code: 10015): Unknown Webhook
2024-07-23 23:12:21,216 - INFO - logging in using static token
2024-07-23 23:12:23,059 - INFO - Shard ID None has connected to Gateway (Session ID: 33b0a61ab823d9c33aeb3c5b459ec214).
2024-07-23 23:13:03,531 - ERROR - Task exception was never retrieved
future: <Task finished name='CommandTree-invoker' coro=<CommandTree._from_interaction.<locals>.wrapper() done, defined at C:\Python312\Lib\site-packages\discord\app_commands\tree.py:1149> exception=NotFound('404 Not Found (error code: 10015): Unknown Webhook')>
Traceback (most recent call last):
  File "C:\Python312\Lib\site-packages\discord\app_commands\tree.py", line 1310, in _call
    await command._invoke_with_namespace(interaction, namespace)
  File "C:\Python312\Lib\site-packages\discord\app_commands\commands.py", line 879, in _invoke_with_namespace
    if not await self._check_can_run(interaction):
           ^^^^^^^^^^^^^^^^^^^^^^^^^^^^^^^^^^^^^^
  File "C:\Python312\Lib\site-packages\discord\app_commands\commands.py", line 1017, in _check_can_run
    return await async_all(f(interaction) for f in predicates)
           ^^^^^^^^^^^^^^^^^^^^^^^^^^^^^^^^^^^^^^^^^^^^^^^^^^^
  File "C:\Python312\Lib\site-packages\discord\utils.py", line 706, in async_all
    elem = await elem
           ^^^^^^^^^^
  File "C:\Users\SOUNAK BERA\Bot Stuff\FundTransfer-Bot\cogs\grouppayout.py", line 17, in predicate
    raise discord.app_commands.MissingPermissions(missing_permissions=role_names)
discord.app_commands.errors.MissingPermissions: You are missing Techie permission(s) to run this command.

During handling of the above exception, another exception occurred:

Traceback (most recent call last):
  File "C:\Python312\Lib\site-packages\discord\app_commands\tree.py", line 1151, in wrapper
    await self._call(interaction)
  File "C:\Python312\Lib\site-packages\discord\app_commands\tree.py", line 1313, in _call
    await command._invoke_error_handlers(interaction, e)
  File "C:\Python312\Lib\site-packages\discord\app_commands\commands.py", line 800, in _invoke_error_handlers
    await self.on_error(self.binding, interaction, error)  # type: ignore
    ^^^^^^^^^^^^^^^^^^^^^^^^^^^^^^^^^^^^^^^^^^^^^^^^^^^^^
  File "C:\Users\SOUNAK BERA\Bot Stuff\FundTransfer-Bot\cogs\grouppayout.py", line 136, in group_payout_error
    await interaction.followup.send(f"You do not have the required roles to use this command: {missing_roles}", ephemeral=True)
  File "C:\Python312\Lib\site-packages\discord\webhook\async_.py", line 1843, in send
    data = await adapter.execute_webhook(
           ^^^^^^^^^^^^^^^^^^^^^^^^^^^^^^
  File "C:\Python312\Lib\site-packages\discord\webhook\async_.py", line 221, in request
    raise NotFound(response, data)
discord.errors.NotFound: 404 Not Found (error code: 10015): Unknown Webhook
2024-07-23 23:13:22,772 - ERROR - Task exception was never retrieved
future: <Task finished name='CommandTree-invoker' coro=<CommandTree._from_interaction.<locals>.wrapper() done, defined at C:\Python312\Lib\site-packages\discord\app_commands\tree.py:1149> exception=NotFound('404 Not Found (error code: 10015): Unknown Webhook')>
Traceback (most recent call last):
  File "C:\Python312\Lib\site-packages\discord\app_commands\tree.py", line 1310, in _call
    await command._invoke_with_namespace(interaction, namespace)
  File "C:\Python312\Lib\site-packages\discord\app_commands\commands.py", line 879, in _invoke_with_namespace
    if not await self._check_can_run(interaction):
           ^^^^^^^^^^^^^^^^^^^^^^^^^^^^^^^^^^^^^^
  File "C:\Python312\Lib\site-packages\discord\app_commands\commands.py", line 1017, in _check_can_run
    return await async_all(f(interaction) for f in predicates)
           ^^^^^^^^^^^^^^^^^^^^^^^^^^^^^^^^^^^^^^^^^^^^^^^^^^^
  File "C:\Python312\Lib\site-packages\discord\utils.py", line 706, in async_all
    elem = await elem
           ^^^^^^^^^^
  File "C:\Users\SOUNAK BERA\Bot Stuff\FundTransfer-Bot\cogs\grouppayout.py", line 17, in predicate
    raise discord.app_commands.MissingPermissions(missing_permissions=role_names)
discord.app_commands.errors.MissingPermissions: You are missing Techie permission(s) to run this command.

During handling of the above exception, another exception occurred:

Traceback (most recent call last):
  File "C:\Python312\Lib\site-packages\discord\app_commands\tree.py", line 1151, in wrapper
    await self._call(interaction)
  File "C:\Python312\Lib\site-packages\discord\app_commands\tree.py", line 1313, in _call
    await command._invoke_error_handlers(interaction, e)
  File "C:\Python312\Lib\site-packages\discord\app_commands\commands.py", line 800, in _invoke_error_handlers
    await self.on_error(self.binding, interaction, error)  # type: ignore
    ^^^^^^^^^^^^^^^^^^^^^^^^^^^^^^^^^^^^^^^^^^^^^^^^^^^^^
  File "C:\Users\SOUNAK BERA\Bot Stuff\FundTransfer-Bot\cogs\grouppayout.py", line 136, in group_payout_error
    await interaction.followup.send(f"You do not have the required roles to use this command: {missing_roles}", ephemeral=True)
  File "C:\Python312\Lib\site-packages\discord\webhook\async_.py", line 1843, in send
    data = await adapter.execute_webhook(
           ^^^^^^^^^^^^^^^^^^^^^^^^^^^^^^
  File "C:\Python312\Lib\site-packages\discord\webhook\async_.py", line 221, in request
    raise NotFound(response, data)
discord.errors.NotFound: 404 Not Found (error code: 10015): Unknown Webhook
2024-07-23 23:15:27,956 - INFO - logging in using static token
2024-07-23 23:15:30,692 - INFO - Shard ID None has connected to Gateway (Session ID: 4aff5cb3405475e66c8cb8391ae59c32).
2024-07-23 23:16:26,924 - ERROR - Task exception was never retrieved
future: <Task finished name='CommandTree-invoker' coro=<CommandTree._from_interaction.<locals>.wrapper() done, defined at C:\Python312\Lib\site-packages\discord\app_commands\tree.py:1149> exception=NotFound('404 Not Found (error code: 10015): Unknown Webhook')>
Traceback (most recent call last):
  File "C:\Python312\Lib\site-packages\discord\app_commands\tree.py", line 1310, in _call
    await command._invoke_with_namespace(interaction, namespace)
  File "C:\Python312\Lib\site-packages\discord\app_commands\commands.py", line 879, in _invoke_with_namespace
    if not await self._check_can_run(interaction):
           ^^^^^^^^^^^^^^^^^^^^^^^^^^^^^^^^^^^^^^
  File "C:\Python312\Lib\site-packages\discord\app_commands\commands.py", line 1017, in _check_can_run
    return await async_all(f(interaction) for f in predicates)
           ^^^^^^^^^^^^^^^^^^^^^^^^^^^^^^^^^^^^^^^^^^^^^^^^^^^
  File "C:\Python312\Lib\site-packages\discord\utils.py", line 706, in async_all
    elem = await elem
           ^^^^^^^^^^
  File "C:\Users\SOUNAK BERA\Bot Stuff\FundTransfer-Bot\cogs\grouppayout.py", line 17, in predicate
    raise discord.app_commands.MissingPermissions(missing_permissions=role_names)
discord.app_commands.errors.MissingPermissions: You are missing Techie permission(s) to run this command.

During handling of the above exception, another exception occurred:

Traceback (most recent call last):
  File "C:\Python312\Lib\site-packages\discord\app_commands\tree.py", line 1151, in wrapper
    await self._call(interaction)
  File "C:\Python312\Lib\site-packages\discord\app_commands\tree.py", line 1313, in _call
    await command._invoke_error_handlers(interaction, e)
  File "C:\Python312\Lib\site-packages\discord\app_commands\commands.py", line 800, in _invoke_error_handlers
    await self.on_error(self.binding, interaction, error)  # type: ignore
    ^^^^^^^^^^^^^^^^^^^^^^^^^^^^^^^^^^^^^^^^^^^^^^^^^^^^^
  File "C:\Users\SOUNAK BERA\Bot Stuff\FundTransfer-Bot\cogs\grouppayout.py", line 134, in group_payout_error
    await interaction.followup.send(f"You do not have the required roles to use this command: {missing_roles}", ephemeral=True)
  File "C:\Python312\Lib\site-packages\discord\webhook\async_.py", line 1843, in send
    data = await adapter.execute_webhook(
           ^^^^^^^^^^^^^^^^^^^^^^^^^^^^^^
  File "C:\Python312\Lib\site-packages\discord\webhook\async_.py", line 221, in request
    raise NotFound(response, data)
discord.errors.NotFound: 404 Not Found (error code: 10015): Unknown Webhook
2024-07-23 23:21:26,994 - INFO - logging in using static token
2024-07-23 23:21:29,053 - INFO - Shard ID None has connected to Gateway (Session ID: d17468121e7ad54c4252741e371eb74e).
2024-07-23 23:22:04,724 - INFO - logging in using static token
2024-07-23 23:22:06,613 - INFO - Shard ID None has connected to Gateway (Session ID: bd062f5b162e091f2ca63b87e598e082).
2024-07-23 23:22:57,582 - ERROR - Task exception was never retrieved
future: <Task finished name='CommandTree-invoker' coro=<CommandTree._from_interaction.<locals>.wrapper() done, defined at C:\Python312\Lib\site-packages\discord\app_commands\tree.py:1149> exception=NotFound('404 Not Found (error code: 10015): Unknown Webhook')>
Traceback (most recent call last):
  File "C:\Python312\Lib\site-packages\discord\app_commands\tree.py", line 1310, in _call
    await command._invoke_with_namespace(interaction, namespace)
  File "C:\Python312\Lib\site-packages\discord\app_commands\commands.py", line 879, in _invoke_with_namespace
    if not await self._check_can_run(interaction):
           ^^^^^^^^^^^^^^^^^^^^^^^^^^^^^^^^^^^^^^
  File "C:\Python312\Lib\site-packages\discord\app_commands\commands.py", line 1017, in _check_can_run
    return await async_all(f(interaction) for f in predicates)
           ^^^^^^^^^^^^^^^^^^^^^^^^^^^^^^^^^^^^^^^^^^^^^^^^^^^
  File "C:\Python312\Lib\site-packages\discord\utils.py", line 706, in async_all
    elem = await elem
           ^^^^^^^^^^
  File "C:\Users\SOUNAK BERA\Bot Stuff\FundTransfer-Bot\cogs\grouppayout.py", line 17, in predicate
    raise discord.app_commands.MissingPermissions(missing_permissions=role_names)
discord.app_commands.errors.MissingPermissions: You are missing Techie permission(s) to run this command.

During handling of the above exception, another exception occurred:

Traceback (most recent call last):
  File "C:\Python312\Lib\site-packages\discord\app_commands\tree.py", line 1151, in wrapper
    await self._call(interaction)
  File "C:\Python312\Lib\site-packages\discord\app_commands\tree.py", line 1313, in _call
    await command._invoke_error_handlers(interaction, e)
  File "C:\Python312\Lib\site-packages\discord\app_commands\commands.py", line 800, in _invoke_error_handlers
    await self.on_error(self.binding, interaction, error)  # type: ignore
    ^^^^^^^^^^^^^^^^^^^^^^^^^^^^^^^^^^^^^^^^^^^^^^^^^^^^^
  File "C:\Users\SOUNAK BERA\Bot Stuff\FundTransfer-Bot\cogs\grouppayout.py", line 137, in group_payout_error
    await interaction.followup.send(f"You do not have the required roles to use this command: {missing_roles}", ephemeral=True)
  File "C:\Python312\Lib\site-packages\discord\webhook\async_.py", line 1843, in send
    data = await adapter.execute_webhook(
           ^^^^^^^^^^^^^^^^^^^^^^^^^^^^^^
  File "C:\Python312\Lib\site-packages\discord\webhook\async_.py", line 221, in request
    raise NotFound(response, data)
discord.errors.NotFound: 404 Not Found (error code: 10015): Unknown Webhook
2024-07-23 23:29:11,611 - INFO - logging in using static token
2024-07-23 23:29:13,535 - INFO - Shard ID None has connected to Gateway (Session ID: 7dfbaa2942310f440f3a5a8de17cd121).
2024-07-23 23:31:22,416 - INFO - logging in using static token
2024-07-23 23:31:24,308 - INFO - Shard ID None has connected to Gateway (Session ID: 5482663797920f1d1939859fa532f0c4).
2024-07-23 23:33:50,189 - INFO - logging in using static token
2024-07-23 23:33:52,163 - INFO - Shard ID None has connected to Gateway (Session ID: 669c4dec59969b59305bb959c1785d36).
